
fn exceptionFunc()
{
	try{
		try{ 
			try{
				try{ 
					throw "exceptionFunc";
				} catch(ex){ 
					throw ex; 
				}
			} catch(ex) {
				throw ex;
			}
		} catch(ex) {
			throw ex;
		}
	} catch(ex) {
		throw ex;
	}
}

fn main()
{
	let str = undefined;
	
	try{

		try{
			exceptionFunc();
		} catch(ex){
			throw ex;
		}

	}catch(ex){
		str = ex;
	}

	return str;
}